Workbook

Sheet Kapa Stationen
A1: ONS | B1: PV-Leistung an ONS | C1: Installierte Trafoleistung | D1: Übrige Trafokapazität | E1: Übrige Trafokapazität bei Gleichzeitigkeitsfaktor 0,7 | F1: Umspannwerk | G1: X-Koordinate | H1: Y-Koordinate | I1: Breitengrad | J1: Längengrad
A2: 01TS0257 | B2: 154.11975 | C2: 400 | D2: 245.88025 | E2: 292.11617 | F2: UW_ROMER | G2: =VLOOKUP(A2,Tabelle1!A:F,3,FALSE) -> 514715.05 | H2: =VLOOKUP(A2,Tabelle1!A:F,4,FALSE) -> 5445929.3 | I2: =VLOOKUP(A2,Tabelle1!A:F,5,FALSE) -> 9.201855 | J2: =VLOOKUP(A2,Tabelle1!A:F,6,FALSE) -> 49.166002
A3: 01TS0334 | B3: 154.98975 | C3: #N/A | D3: #N/A | E3: #N/A | F3: #N/A | G3: =VLOOKUP(A3,Tabelle1!A:F,3,FALSE) -> 514387.05 | H3: =VLOOKUP(A3,Tabelle1!A:F,4,FALSE) -> 5445858.8 | I3: =VLOOKUP(A3,Tabelle1!A:F,5,FALSE) -> 9.1973531 | J3: =VLOOKUP(A3,Tabelle1!A:F,6,FALSE) -> 49.165376
A4: 01TS0795 | B4: 144.29475 | C4: 630 | D4: 485.70525 | E4: 528.99367 | F4: UW_ROMER | G4: =VLOOKUP(A4,Tabelle1!A:F,3,FALSE) -> 514682.96 | H4: =VLOOKUP(A4,Tabelle1!A:F,4,FALSE) -> 5445372.5 | I4: =VLOOKUP(A4,Tabelle1!A:F,5,FALSE) -> 9.2013945 | J4: =VLOOKUP(A4,Tabelle1!A:F,6,FALSE) -> 49.160994
A5: 01TS0798 | B5: 181.01475 | C5: 400 | D5: 218.98525 | E5: 273.28967 | F5: UW_ROMER | G5: =VLOOKUP(A5,Tabelle1!A:F,3,FALSE) -> 514749.37 | H5: =VLOOKUP(A5,Tabelle1!A:F,4,FALSE) -> 5445697.8 | I5: =VLOOKUP(A5,Tabelle1!A:F,5,FALSE) -> 9.2023173 | J5: =VLOOKUP(A5,Tabelle1!A:F,6,FALSE) -> 49.163918
A6: 01TS0163 | B6: 166.79 | C6: 715 | D6: 548.21 | E6: 598.247 | F6: UW_BOEKI | G6: =VLOOKUP(A6,Tabelle1!A:F,3,FALSE) -> 513126.86 | H6: =VLOOKUP(A6,Tabelle1!A:F,4,FALSE) -> 5444023.1 | I6: =VLOOKUP(A6,Tabelle1!A:F,5,FALSE) -> 9.1800068 | J6: =VLOOKUP(A6,Tabelle1!A:F,6,FALSE) -> 49.148891
A7: 01TS0372 | B7: 241.86 | C7: 400 | D7: 158.14 | E7: 230.698 | F7: UW_BOEKI | G7: =VLOOKUP(A7,Tabelle1!A:F,3,FALSE) -> 512992.26 | H7: =VLOOKUP(A7,Tabelle1!A:F,4,FALSE) -> 5443685.4 | I7: =VLOOKUP(A7,Tabelle1!A:F,5,FALSE) -> 9.1781502 | J7: =VLOOKUP(A7,Tabelle1!A:F,6,FALSE) -> 49.145856
A8: 01TS0827 | B8: 185.605 | C8: 630 | D8: 444.395 | E8: 500.0765 | F8: UW_BOEKI | G8: =VLOOKUP(A8,Tabelle1!A:F,3,FALSE) -> 512944.63 | H8: =VLOOKUP(A8,Tabelle1!A:F,4,FALSE) -> 5443928.3 | I8: =VLOOKUP(A8,Tabelle1!A:F,5,FALSE) -> 9.1775049 | J8: =VLOOKUP(A8,Tabelle1!A:F,6,FALSE) -> 49.148042
A9: 01TS0272 | B9: 38.6775 | C9: 400 | D9: 361.3225 | E9: 372.92575 | F9: UW_BOEKI | G9: =VLOOKUP(A9,Tabelle1!A:F,3,FALSE) -> 513672.09 | H9: =VLOOKUP(A9,Tabelle1!A:F,4,FALSE) -> 5441588.3 | I9: =VLOOKUP(A9,Tabelle1!A:F,5,FALSE) -> 9.1874008 | J9: =VLOOKUP(A9,Tabelle1!A:F,6,FALSE) -> 49.126978
A10: 01TS0333 | B10: 134.1225 | C10: 315 | D10: 180.8775 | E10: 221.11425 | F10: UW_BOEKI | G10: =VLOOKUP(A10,Tabelle1!A:F,3,FALSE) -> 513444.75 | H10: =VLOOKUP(A10,Tabelle1!A:F,4,FALSE) -> 5441815.1 | I10: =VLOOKUP(A10,Tabelle1!A:F,5,FALSE) -> 9.1842923 | J10: =VLOOKUP(A10,Tabelle1!A:F,6,FALSE) -> 49.129023
A11: 01TS0397 | B11: 68.9725 | C11: 1130 | D11: 1061.0275 | E11: 1081.7193 | F11: UW_BOEKI | G11: =VLOOKUP(A11,Tabelle1!A:F,3,FALSE) -> 513665.79 | H11: =VLOOKUP(A11,Tabelle1!A:F,4,FALSE) -> 5441972.6 | I11: =VLOOKUP(A11,Tabelle1!A:F,5,FALSE) -> 9.1873275 | J11: =VLOOKUP(A11,Tabelle1!A:F,6,FALSE) -> 49.130434
A12: 01TS0431 | B12: 33.1475 | C12: 400 | D12: 366.8525 | E12: 376.79675 | F12: UW_BOEKI | G12: =VLOOKUP(A12,Tabelle1!A:F,3,FALSE) -> 513460.44 | H12: =VLOOKUP(A12,Tabelle1!A:F,4,FALSE) -> 5441544.2 | I12: =VLOOKUP(A12,Tabelle1!A:F,5,FALSE) -> 9.1844983 | J12: =VLOOKUP(A12,Tabelle1!A:F,6,FALSE) -> 49.126586
A13: 01TS0609 | B13: 33.1475 | C13: 400 | D13: 366.8525 | E13: 376.79675 | F13: UW_BOEKI | G13: =VLOOKUP(A13,Tabelle1!A:F,3,FALSE) -> 514015.93 | H13: =VLOOKUP(A13,Tabelle1!A:F,4,FALSE) -> 5441828.1 | I13: =VLOOKUP(A13,Tabelle1!A:F,5,FALSE) -> 9.1921221 | J13: =VLOOKUP(A13,Tabelle1!A:F,6,FALSE) -> 49.129126
A14: 01TS0623 | B14: 52.9275 | C14: 250 | D14: 197.0725 | E14: 212.95075 | F14: UW_BOEKI | G14: =VLOOKUP(A14,Tabelle1!A:F,3,FALSE) -> 513371.41 | H14: =VLOOKUP(A14,Tabelle1!A:F,4,FALSE) -> 5442058.9 | I14: =VLOOKUP(A14,Tabelle1!A:F,5,FALSE) -> 9.1832951 | J14: =VLOOKUP(A14,Tabelle1!A:F,6,FALSE) -> 49.131217
A15: 01TSXXXX | B15: 109.415 | C15: #N/A | D15: #N/A | E15: #N/A | F15: #N/A | G15: =VLOOKUP(A15,Tabelle1!A:F,3,FALSE) -> #N/A | H15: =VLOOKUP(A15,Tabelle1!A:F,4,FALSE) -> #N/A | I15: =VLOOKUP(A15,Tabelle1!A:F,5,FALSE) -> #N/A | J15: =VLOOKUP(A15,Tabelle1!A:F,6,FALSE) -> #N/A
A16: 01TS0785 | B16: 155.338 | C16: 400 | D16: 244.662 | E16: 291.2634 | F16: UW_BHOXX | G16: =VLOOKUP(A16,Tabelle1!A:F,3,FALSE) -> 507542.72 | H16: =VLOOKUP(A16,Tabelle1!A:F,4,FALSE) -> 5447614.8 | I16: =VLOOKUP(A16,Tabelle1!A:F,5,FALSE) -> 9.1034998 | J16: =VLOOKUP(A16,Tabelle1!A:F,6,FALSE) -> 49.181293
A17: 05TS0022 | B17: 247.33333 | C17: 630 | D17: 382.66667 | E17: 456.86667 | F17: UW_GROGH | G17: =VLOOKUP(A17,Tabelle1!A:F,3,FALSE) -> 508693.23 | H17: =VLOOKUP(A17,Tabelle1!A:F,4,FALSE) -> 5443371.7 | I17: =VLOOKUP(A17,Tabelle1!A:F,5,FALSE) -> 9.1191952 | J17: =VLOOKUP(A17,Tabelle1!A:F,6,FALSE) -> 49.14311
A18: 05TS0015 | B18: 222.53833 | C18: 400 | D18: 177.46167 | E18: 244.22317 | F18: UW_GROGH | G18: =VLOOKUP(A18,Tabelle1!A:F,3,FALSE) -> 508240.4 | H18: =VLOOKUP(A18,Tabelle1!A:F,4,FALSE) -> 5443290.9 | I18: =VLOOKUP(A18,Tabelle1!A:F,5,FALSE) -> 9.1129847 | J18: =VLOOKUP(A18,Tabelle1!A:F,6,FALSE) -> 49.14239
A19: 05TS0057 | B19: 455.92833 | C19: 400 | D19: -55.928333 | E19: 80.850167 | F19: UW_GROGH | G19: =VLOOKUP(A19,Tabelle1!A:F,3,FALSE) -> 508419.8 | H19: =VLOOKUP(A19,Tabelle1!A:F,4,FALSE) -> 5443179.2 | I19: =VLOOKUP(A19,Tabelle1!A:F,5,FALSE) -> 9.1154421 | J19: =VLOOKUP(A19,Tabelle1!A:F,6,FALSE) -> 49.141383
A20: 05TS0061 | B20: 495.36 | C20: 630 | D20: 134.64 | E20: 283.248 | F20: UW_GROGH | G20: =VLOOKUP(A20,Tabelle1!A:F,3,FALSE) -> 509428.6 | H20: =VLOOKUP(A20,Tabelle1!A:F,4,FALSE) -> 5444028.1 | I20: =VLOOKUP(A20,Tabelle1!A:F,5,FALSE) -> 9.1292934 | J20: =VLOOKUP(A20,Tabelle1!A:F,6,FALSE) -> 49.149004
A21: 08TS0032 | B21: 151.856 | C21: 630 | D21: 478.144 | E21: 523.7008 | F21: UW_GROGH | G21: =VLOOKUP(A21,Tabelle1!A:F,3,FALSE) -> 514314.78 | H21: =VLOOKUP(A21,Tabelle1!A:F,4,FALSE) -> 5436635.9 | I21: =VLOOKUP(A21,Tabelle1!A:F,5,FALSE) -> 9.1960345 | J21: =VLOOKUP(A21,Tabelle1!A:F,6,FALSE) -> 49.082414
A22: 01TS0563 | B22: 198.7 | C22: 400 | D22: 201.3 | E22: 260.91 | F22: UW_BHOXX | G22: =VLOOKUP(A22,Tabelle1!A:F,3,FALSE) -> 508327.22 | H22: =VLOOKUP(A22,Tabelle1!A:F,4,FALSE) -> 5447413.3 | I22: =VLOOKUP(A22,Tabelle1!A:F,5,FALSE) -> 9.1142603 | J22: =VLOOKUP(A22,Tabelle1!A:F,6,FALSE) -> 49.179471
A23: 05TS0065 | B23: 245.015 | C23: 400 | D23: 154.985 | E23: 228.4895 | F23: UW_GROGH | G23: =VLOOKUP(A23,Tabelle1!A:F,3,FALSE) -> 509419.3 | H23: =VLOOKUP(A23,Tabelle1!A:F,4,FALSE) -> 5442764 | I23: =VLOOKUP(A23,Tabelle1!A:F,5,FALSE) -> 9.1291363 | J23: =VLOOKUP(A23,Tabelle1!A:F,6,FALSE) -> 49.137633
A24: 05TS0070 | B24: 73.48 | C24: 630 | D24: 556.52 | E24: 578.564 | F24: UW_GROGH | G24: =VLOOKUP(A24,Tabelle1!A:F,3,FALSE) -> 507103.9 | H24: =VLOOKUP(A24,Tabelle1!A:F,4,FALSE) -> 5443719.1 | I24: =VLOOKUP(A24,Tabelle1!A:F,5,FALSE) -> 9.0974096 | J24: =VLOOKUP(A24,Tabelle1!A:F,6,FALSE) -> 49.146256
A25: 06TS0009 | B25: 102.985 | C25: 400 | D25: 297.015 | E25: 327.9105 | F25: UW_UGRBH | G25: =VLOOKUP(A25,Tabelle1!A:F,3,FALSE) -> 521035.7 | H25: =VLOOKUP(A25,Tabelle1!A:F,4,FALSE) -> 5439125.9 | I25: =VLOOKUP(A25,Tabelle1!A:F,5,FALSE) -> 9.288203 | J25: =VLOOKUP(A25,Tabelle1!A:F,6,FALSE) -> 49.104619
A26: 06TS0027 | B26: 176.635 | C26: 400 | D26: 223.365 | E26: 276.3555 | F26: UW_UGRBH | G26: =VLOOKUP(A26,Tabelle1!A:F,3,FALSE) -> 520295.11 | H26: =VLOOKUP(A26,Tabelle1!A:F,4,FALSE) -> 5437727.8 | I26: =VLOOKUP(A26,Tabelle1!A:F,5,FALSE) -> 9.2779864 | J26: =VLOOKUP(A26,Tabelle1!A:F,6,FALSE) -> 49.092067
A27: 07TS0018 | B27: 255.31 | C27: 400 | D27: 144.69 | E27: 221.283 | F27: UW_UGRBH | G27: =VLOOKUP(A27,Tabelle1!A:F,3,FALSE) -> 514761.03 | H27: =VLOOKUP(A27,Tabelle1!A:F,4,FALSE) -> 5438631.8 | I27: =VLOOKUP(A27,Tabelle1!A:F,5,FALSE) -> 9.2022185 | J27: =VLOOKUP(A27,Tabelle1!A:F,6,FALSE) -> 49.100357
... A37: 01TS0613 | B37: 188.46933 | C37: 400 | D37: 211.53067 | E37: 268.07147 | F37: UW_BHOXX | G37: =VLOOKUP(A37,Tabelle1!A:F,3,FALSE) -> 514206.6 | H37: =VLOOKUP(A37,Tabelle1!A:F,4,FALSE) -> 5446373.7 | I37: =VLOOKUP(A37,Tabelle1!A:F,5,FALSE) -> 9.194896 | J37: =VLOOKUP(A37,Tabelle1!A:F,6,FALSE) -> 49.170011
A38: 06TS6013 | B38: 17.99 | C38: #N/A | D38: #N/A | E38: #N/A | F38: #N/A | G38: =VLOOKUP(A38,Tabelle1!A:F,3,FALSE) -> #N/A | H38: =VLOOKUP(A38,Tabelle1!A:F,4,FALSE) -> #N/A | I38: =VLOOKUP(A38,Tabelle1!A:F,5,FALSE) -> #N/A | J38: =VLOOKUP(A38,Tabelle1!A:F,6,FALSE) -> #N/A
A39: 03TS0024 | B39: 301.565 | C39: 400 | D39: 98.435 | E39: 188.9045 | F39: UW_LASTD | G39: =VLOOKUP(A39,Tabelle1!A:F,3,FALSE) -> 514028.07 | H39: =VLOOKUP(A39,Tabelle1!A:F,4,FALSE) -> 5432981.8 | I39: =VLOOKUP(A39,Tabelle1!A:F,5,FALSE) -> 9.1919815 | J39: =VLOOKUP(A39,Tabelle1!A:F,6,FALSE) -> 49.049551
A40: 01TS0887 | B40: 43 | C40: 400 | D40: 357 | E40: 369.9 | F40: UW_SONHN | G40: =VLOOKUP(A40,Tabelle1!A:F,3,FALSE) -> 515756 | H40: =VLOOKUP(A40,Tabelle1!A:F,4,FALSE) -> 5441997 | I40: =VLOOKUP(A40,Tabelle1!A:F,5,FALSE) -> 9.2159804 | J40: =VLOOKUP(A40,Tabelle1!A:F,6,FALSE) -> 49.130604
A41: 01TS0683 | B41: 99 | C41: 400 | D41: 301 | E41: 330.7 | F41: UW_SWPXX | G41: =VLOOKUP(A41,Tabelle1!A:F,3,FALSE) -> 515664.02 | H41: =VLOOKUP(A41,Tabelle1!A:F,4,FALSE) -> 5444757.5 | I41: =VLOOKUP(A41,Tabelle1!A:F,5,FALSE) -> 9.2148269 | J41: =VLOOKUP(A41,Tabelle1!A:F,6,FALSE) -> 49.155438
A42: 05TS0047 | B42: 577.652 | C42: 630 | D42: 52.348 | E42: 225.6436 | F42: UW_GROGH | G42: =VLOOKUP(A42,Tabelle1!A:F,3,FALSE) -> 507692.23 | H42: =VLOOKUP(A42,Tabelle1!A:F,4,FALSE) -> 5443264.5 | I42: =VLOOKUP(A42,Tabelle1!A:F,5,FALSE) -> 9.1054682 | J42: =VLOOKUP(A42,Tabelle1!A:F,6,FALSE) -> 49.14216
A43: 07TS0004 | B43: 158.157 | C43: 400 | D43: 241.843 | E43: 289.2901 | F43: UW_UGRBH | G43: =VLOOKUP(A43,Tabelle1!A:F,3,FALSE) -> 515423.34 | H43: =VLOOKUP(A43,Tabelle1!A:F,4,FALSE) -> 5438633.8 | I43: =VLOOKUP(A43,Tabelle1!A:F,5,FALSE) -> 9.2112918 | J43: =VLOOKUP(A43,Tabelle1!A:F,6,FALSE) -> 49.100359
A44: 01TS0723 | B44: 152.805 | C44: 630 | D44: 477.195 | E44: 523.0365 | F44: UW_BOEKI | G44: =VLOOKUP(A44,Tabelle1!A:F,3,FALSE) -> 511002.18 | H44: =VLOOKUP(A44,Tabelle1!A:F,4,FALSE) -> 5440756.9 | I44: =VLOOKUP(A44,Tabelle1!A:F,5,FALSE) -> 9.1507824 | J44: =VLOOKUP(A44,Tabelle1!A:F,6,FALSE) -> 49.119552
A45: 02TS0060 | B45: 254.855 | C45: 630 | D45: 375.145 | E45: 451.6015 | F45: UW_LAUFN | G45: =VLOOKUP(A45,Tabelle1!A:F,3,FALSE) -> 510868.48 | H45: =VLOOKUP(A45,Tabelle1!A:F,4,FALSE) -> 5435565 | I45: =VLOOKUP(A45,Tabelle1!A:F,5,FALSE) -> 9.1488104 | J45: =VLOOKUP(A45,Tabelle1!A:F,6,FALSE) -> 49.072851
A46: 01TS0021 | B46: 59.328 | C46: 800 | D46: 740.672 | E46: 758.4704 | F46: UW_SONHN | G46: =VLOOKUP(A46,Tabelle1!A:F,3,FALSE) -> 513821.24 | H46: =VLOOKUP(A46,Tabelle1!A:F,4,FALSE) -> 5440724 | I46: =VLOOKUP(A46,Tabelle1!A:F,5,FALSE) -> 9.1894156 | J46: =VLOOKUP(A46,Tabelle1!A:F,6,FALSE) -> 49.119199
A47: 01TS0131 | B47: 142.07967 | C47: 400 | D47: 257.92033 | E47: 300.54423 | F47: UW_SONHN | G47: =VLOOKUP(A47,Tabelle1!A:F,3,FALSE) -> 513454.15 | H47: =VLOOKUP(A47,Tabelle1!A:F,4,FALSE) -> 5440497.4 | I47: =VLOOKUP(A47,Tabelle1!A:F,5,FALSE) -> 9.1843772 | J47: =VLOOKUP(A47,Tabelle1!A:F,6,FALSE) -> 49.117169
A48: 01TS0286 | B48: 77.934667 | C48: #N/A | D48: #N/A | E48: #N/A | F48: #N/A | G48: =VLOOKUP(A48,Tabelle1!A:F,3,FALSE) -> #N/A | H48: =VLOOKUP(A48,Tabelle1!A:F,4,FALSE) -> #N/A | I48: =VLOOKUP(A48,Tabelle1!A:F,5,FALSE) -> #N/A | J48: =VLOOKUP(A48,Tabelle1!A:F,6,FALSE) -> #N/A
A49: 01TS0465 | B49: 73.689667 | C49: 250 | D49: 176.31033 | E49: 198.41723 | F49: UW_SONHN | G49: =VLOOKUP(A49,Tabelle1!A:F,3,FALSE) -> 513282.59 | H49: =VLOOKUP(A49,Tabelle1!A:F,4,FALSE) -> 5440556.9 | I49: =VLOOKUP(A49,Tabelle1!A:F,5,FALSE) -> 9.1820281 | J49: =VLOOKUP(A49,Tabelle1!A:F,6,FALSE) -> 49.117708
...

Sheet Kapa Umspannwerke
A1: UW | B1: Verfügbare Einspeisekapazität in MW
A2: SWPXX | B2: 77.1
A3: BADHN | B3: 80
A4: BHOFE | B4: 78.8
A5: BOEKI | B5: 50
A6: KETER | B6: 80
A7: ROMER | B7: 48.6
A8: SONHN | B8: 60
A9: LAUFN | B9: 76.7
A10: LASTD | B10: 53.3
A11: UGRBH | B11: 0
A12: GROGH | B12: 0

Sheet Tabelle1
B1: Stationsnummer | C1: X-Koordinate | D1: Y-Koordinate | E1: Breitengrad | F1: Längengrad
A2: 01TS0038 | B2: 01TS0038 | C2: 514803.7 | D2: 5442436.6 | E2: 9.2029427 | F2: 49.134582
A3: 01TS0039 | B3: 01TS0039 | C3: 514188.06 | D3: 5441390 | E3: 9.1944661 | F3: 49.125182
A4: 01TS0010 | B4: 01TS0010 | C4: 514336.99 | D4: 5440958.3 | E4: 9.1964921 | F4: 49.121295
A5: 01TS0100 | B5: 01TS0100 | C5: 514755.45 | D5: 5446226.6 | E5: 9.2024201 | F5: 49.168675
A6: 01TS0101 | B6: 01TS0101 | C6: 514975.09 | D6: 5443124 | E6: 9.2053178 | F6: 49.140761
A7: 01TS0103 | B7: 01TS0103 | C7: 515357.33 | D7: 5441937.5 | E7: 9.2105133 | F7: 49.130079
A8: 01TS0105 | B8: 01TS0105 | C8: 517315.03 | D8: 5442913.9 | E8: 9.2373905 | F8: 49.13881
A9: 01TS0108 | B9: 01TS0108 | C9: 517745.65 | D9: 5442560.2 | E9: 9.2432787 | F9: 49.135616
A10: 01TS0111 | B10: 01TS0111 | C10: 515476.42 | D10: 5444297 | E10: 9.2122363 | F10: 49.1513
A11: 01TS0112 | B11: 01TS0112 | C11: 515538.34 | D11: 5444407.8 | E11: 9.2130897 | F11: 49.152295
A12: 01TS0113 | B12: 01TS0113 | C12: 515418.99 | D12: 5444506.1 | E12: 9.2114568 | F12: 49.153183
A13: 01TS0114 | B13: 01TS0114 | C13: 515530.84 | D13: 5444538 | E13: 9.2129919 | F13: 49.153467
... A1074: 02TS0087 | B1074: 02TS0087_In den Herrenäckern 11 | C1074: 511395.9 | D1074: 5435044.6 | E1074: 9.1560171 | F1074: 49.06816

Sheet Tabelle3
A1: Name | C1: Abgang
C2: ElmFeeder
A3: SS2B_UW_BADHN_01TS0104 | B3: 01TS0104 | C3: UW_BADHN_110KV_ROM - BAD | D3: UW_BADHN
A4: SS2B_SW_RATXX_01TS0833 | B4: 01TS0833 | C4: UW_BADHN_110KV_ROM - BAD | D4: UW_BADHN
A5: SS2A_UW_BADHN_01TS0104 | B5: 01TS0104 | C5: UW_BADHN_110KV_ROM - BAD | D5: UW_BADHN
A6: SS2A_SW_RATXX_01TS0833 | B6: 01TS0833 | C6: UW_BADHN_110KV_ROM - BAD | D6: UW_BADHN
A7: SS1B_UW_BADHN_01TS0104 | B7: 01TS0104 | C7: UW_BADHN_110KV_ROM - BAD | D7: UW_BADHN
A8: SS1A_UW_BADHN_01TS0104 | B8: 01TS0104 | C8: UW_BADHN_110KV_ROM - BAD | D8: UW_BADHN
A9: BB_01TS0955 | B9: 01TS0955 | C9: UW_BADHN_110KV_ROM - BAD | D9: UW_BADHN
A10: BB_01TS0934 | B10: 01TS0934 | C10: UW_BADHN_110KV_ROM - BAD | D10: UW_BADHN
A11: BB_01TS0930 | B11: 01TS0930 | C11: UW_BADHN_110KV_ROM - BAD | D11: UW_BADHN
A12: BB_01TS0927 | B12: 01TS0927 | C12: UW_BADHN_110KV_ROM - BAD | D12: UW_BADHN
A13: BB_01TS0926 | B13: 01TS0926 | C13: UW_BADHN_110KV_ROM - BAD | D13: UW_BADHN
A14: BB_01TS0925 | B14: 01TS0925 | C14: UW_BADHN_110KV_ROM - BAD | D14: UW_BADHN
... A908: BBA_01TS0349 | B908: 01TS0349 | C908: UW_SWPXX_110KV_HNN-SWP | D908: UW_SWPXX
A909: SS2B_UW_SONHN_01TS0649 | B909: 01TS0649
A910: SS2B_UW_ROMER_01TS0755 | B910: 01TS0755
A911: SS2B_UW_LAUFN_02TS0051 | B911: 02TS0051
A912: SS2B_UW_LASTD_02TS0001 | B912: 02TS0001
A913: SS2B_UW_BOEKI_01TS0160 | B913: 01TS0160
A914: SS2A_UW_SONHN_01TS0649 | B914: 01TS0649
A915: SS2A_UW_ROMER_01TS0755 | B915: 01TS0755
A916: SS2A_UW_LAUFN_02TS0051 | B916: 02TS0051
A917: SS2A_UW_LASTD_02TS0001 | B917: 02TS0001
A918: SS2A_UW_BOEKI_01TS0160 | B918: 01TS0160
A919: SS2A_SW_WANXX_01TS0178 | B919: 01TS0178
A920: BB_02TS0026 | B920: 02TS0026
... A924: BBA_01TS0692 | B924: 01TS0692
A925: Name | C925: Abgang
C926: ElmFeeder
A927: BB_05TS0001 | B927: 05TS0001 | C927: UW_GROGH_J09_Talheim Ost | D927: UW_GROGH
A928: BB_05TS0002 | B928: 05TS0002 | C928: UW_GROGH_J09_Talheim Ost | D928: UW_GROGH
A929: BB_05TS0003 | B929: 05TS0003 | C929: UW_GROGH_J03_Schluchtern | D929: UW_GROGH
A930: BB_05TS0004 | B930: 05TS0004 | C930: UW_GROGH_J03_Schluchtern | D930: UW_GROGH
A931: BB_05TS0006 | B931: 05TS0006 | C931: UW_GROGH_J06_Leingarten | D931: UW_GROGH
A932: BB_05TS0008 | B932: 05TS0008 | C932: UW_GROGH_J03_Schluchtern | D932: UW_GROGH
A933: BB_05TS0009 | B933: 05TS0009 | C933: UW_GROGH_J09_Talheim Ost | D933: UW_GROGH
A934: BB_05TS0010 | B934: 05TS0010 | C934: UW_GROGH_J03_Schluchtern | D934: UW_GROGH
A935: BB_05TS0011 | B935: 05TS0011 | C935: UW_GROGH_J09_Talheim Ost | D935: UW_GROGH
A936: BB_05TS0012 | B936: 05TS0012 | C936: UW_GROGH_J06_Leingarten | D936: UW_GROGH
...
